<mujoco>
	<option>
		<flag sensornoise="enable"/>
	</option>
	<worldbody>
    <light diffuse=".5 .5 .5" pos="0 0 3" dir="0 0 -1"/>
		<geom type="plane" size="1 1 0.1" rgba=".9 0 0 1"/>
		<body pos="0 0 2" euler = "0 90 0 " name = "body1">
			<joint name = "pin" type="hinge" axis = "0 -1 0" pos = "0 0 0"/>
			<geom type="cylinder" size=".05 .5" rgba="0 .9 0 1" mass="1"/>
			<body pos = "0.5 0 -0.5" euler = "0 270 0 " name = "body3">
				<joint name = "pin2" type = "hinge" axis = "0 -1 0" pos="0 0 0.5"/>
				<geom type="cylinder" size=".05 .5" rgba="0 0 0.9 1" mass="1"/>
			</body>
		</body>
		<body pos = "0.5 0 1.5" euler = "0 180 0 " name = "body2">
			<joint name = "free1" type = "free"/>
			<geom type="cylinder" size=".05 .5" rgba="0 .9 0 1" mass="1"/>
		</body>
		<!-- <body pos = "-0.5 0 1.5" euler = "0 180 0 " name = "body3">
			<joint name = "free2" type = "free"/>
			<geom type="cylinder" size=".05 .5" rgba="0 0 0.9 1" mass="1"/>
		</body> -->
	</worldbody>
	<equality>
		<weld active = "true" body1 = "body1" body2 = "body2" relpose="0 0 -0.5 0 0 0 0" />
	</equality>
	<!-- <equality>
		<connect active = "true" body1 = "body1" body2 = "body3" anchor="0 0 -0.5" />
	</equality> -->
	<actuator>
		<motor joint="pin" name="torque" gear="1" ctrllimited="true" ctrlrange="-100 100"/>
		<position name = "position_servo" joint="pin" kp="10"/>
		<velocity name = "velocity_servo" joint="pin" kv="0"/>
	</actuator>
	<sensor>
		<jointpos joint = "pin" noise="0.2"/>
		<jointvel joint = "pin" noise = "1"/>
	</sensor>
</mujoco>
